Workbook
Name CNCodes_ListKey: Parameters_CNCodes!$D$4:$D$572
Name CNCodes_ListNames: Parameters_CNCodes!$C$4:$C$572
Name CNCodes_ListNumbering: Parameters_CNCodes!$F$4:$F$572
Name CNTR_CBAMPeriod: Parameters_Constants!$B$1
Name CNTR_HasEntriesA: A_InstData!$K$124
Name CNTR_IOProcAndPrec: InputOutput!$D$71:$D$100
Name CNTR_IOSupplyChain: InputOutput!$AR$71:$BU$100
Name CNTR_List_ExistGoodTypes: A_InstData!$S$62:$S$71
Name CNTR_List_ExistGoodTypesInclDir: A_InstData!$S$61:$S$71
Name CNTR_List_ExistProdProc: A_InstData!$S$83:$S$92
Name CNTR_List_ExistProdProcNames: A_InstData!$T$83:$T$92
Name CNTR_List_ExistPurchPrec: A_InstData!$S$102:$S$121
Name CNTR_List_ExistPurchPrecNames: A_InstData!$T$102:$T$121
Name CNTR_ListCountriesCode: c_CodeLists!$F$11:$F$277
Name CNTR_ListCountriesName: c_CodeLists!$G$11:$G$277
Name CNTR_ListCurrenciesCode: c_CodeLists!$K$11:$K$177
Name CNTR_ListCurrenciesName: c_CodeLists!$L$11:$L$177
Name CNTR_ListProdProcID: A_InstData!$D$83:$D$92
Name CNTR_ListProdProcNames: A_InstData!$L$83:$L$92
Name CNTR_ListPurchPrecID: A_InstData!$D$102:$D$121
Name CNTR_Matrix_Inv: InputOutput!$E$71:$AH$100
Name CNTR_MatrixPurchPrecRoutes: A_InstData!$X$102:$AB$121
Name CONST_AllProdRoutes: Parameters_Constants!$B$63
Name CONST_CarbonPriceType: Parameters_Constants!$C$45:$I$45
Name CONST_CEMSType: Parameters_Constants!$B$55:$C$55
Name CONST_CNTR_ElecEFMethod: Parameters_Constants!$B$10
Name CONST_CNTR_EmbedEmDir: Parameters_Constants!$B$2
Name CONST_CNTR_EmbedEmInDir: Parameters_Constants!$B$11
Name CONST_CNTR_ListGoodsForCN: Parameters_Constants!$B$133:$S$133
Name CONST_CNTR_PrecNumbering: Parameters_Constants!$BL$89:$BL$106
Name CONST_CNTR_SUM_CO2: Parameters_Constants!$B$3
Name CONST_CNTR_SUM_N2O: Parameters_Constants!$B$5
Name CONST_CNTR_SUM_PFC: Parameters_Constants!$B$4
Name CONST_CNTR_TotProd: Parameters_Constants!$B$12
Name CONST_DataQuality: Parameters_Constants!$B$42:$F$42
Name CONST_DataQualityJustification: Parameters_Constants!$B$44:$D$44
Name CONST_DataVerification: Parameters_Constants!$B$43:$E$43
Name CONST_EFNatGas: Parameters_Constants!$B$13
Name CONST_ElecConsumption: Parameters_Constants!$B$14
Name CONST_ElecSource: Parameters_Constants!$B$15:$H$15
Name CONST_EmDir: Parameters_Constants!$B$7
Name CONST_EmDirHeat: Parameters_Constants!$B$8
Name CONST_EmDirWasteGases: Parameters_Constants!$B$9
Name CONST_ERR_Duplicate: Parameters_Constants!$B$67
Name CONST_ERR_Incomplete: Parameters_Constants!$B$65
Name CONST_ERR_Inconsistent: Parameters_Constants!$B$66
Name CONST_ErrorOrMissing: Parameters_Constants!$B$16
Name CONST_GJ: Parameters_Constants!$B$25
Name CONST_GJpkNm3: Parameters_Constants!$B$36
Name CONST_GJpt: Parameters_Constants!$B$28
Name CONST_GoodToMarket: Parameters_Constants!$B$17
Name CONST_gpNm3: Parameters_Constants!$B$52
Name CONST_GWh: Parameters_Constants!$B$29
Name CONST_GWP_C2F6: Parameters_Constants!$B$78
Name CONST_GWP_CF4: Parameters_Constants!$B$77
Name CONST_GWP_N2O: Parameters_Constants!$B$76
Name CONST_hpa: Parameters_Constants!$B$50
Name CONST_kNm3: Parameters_Constants!$B$27
Name CONST_kNm3pa: Parameters_Constants!$B$53
Name CONST_LinkFromGuidance: Parameters_Constants!$B$73

Sheet 0_Versions
A1: ausblenden | P1: ausblenden | Q1: ausblenden | R1: ausblenden | S1: ausblenden | T1: ausblenden | U1: ausblenden
B2: =Translations!$B$5 | E2: =Translations!$B$11 | G2: =HYPERLINK("#"&ADDRESS(2,3,,,a_Contents!$U$2),a_Contents!$B$2) | I2: =HYPERLINK("#"&ADDRESS(2,3,,,G_FurtherGuidance!$U$2),G_FurtherGuidance!$B$2) | K2: =HYPERLINK("#"&ADDRESS(2,3,,,Summary_Processes!$Y$2),Summary_Processes!$Y$2) | M2: =HYPERLINK("#"&ADDRESS(2,3,,,Summary_Products!$BF$2),Summary_Products!$BF$2) | R2: Print area: | S2: =ADDRESS(ROW($B$6),COLUMN($B$6)) & ":" & ADDRESS(MATCH("PRINT",$P:$P,0),COLUMN($O$6)) | T2: Name of this sheet | U2: =IF(ISERROR(CELL("filename",V2)),"0_Versions",MID(CELL("filename",V2),FIND("]",CELL("filename",V2))+1,1024))
C6: =Translations!$B$6
E8: =Translations!$B$7 | F8: =Translations!$B$8 | G8: =Translations!$B$9
E9: 0.1 | F9: 45159 | G9: =Translations!$B$1889
E10: 1.0 | F10: 45222 | G10: =Translations!$B$1890
G11: =Translations!$B$1891
G12: =Translations!$B$1892
G13: =Translations!$B$1893
G14: =Translations!$B$1894
G15: =Translations!$B$1895
E16: 1.1 | F16: 45237 | G16: =Translations!$B$1896
E17: 2.0 | F17: 45370 | G17: =Translations!$B$1897
G18: =Translations!$B$1898
G19: =Translations!$B$1899
G20: =Translations!$B$1900
G21: =Translations!$B$1901
G22: =Translations!$B$1902
G23: =Translations!$B$1903
G24: =Translations!$B$1904
G25: =Translations!$B$1905
G26: =Translations!$B$1906
G27: =Translations!$B$1907
G28: =Translations!$B$1908
G29: =Translations!$B$1909
G30: =Translations!$B$1910
G31: =Translations!$B$1911
G32: =Translations!$B$1912
G33: =Translations!$B$1913
G34: =Translations!$B$1914
E35: 2.0.1 | F35: 45390 | G35: =Translations!$B$2104
E36: 2.1 | F36: 45448 | G36: =Translations!$B$2116
G37: =Translations!$B$2118
A53: ausblenden | P53: PRINT

Sheet a_Contents
A1: ausblenden | P1: ausblenden | Q1: ausblenden | R1: ausblenden | S1: ausblenden | T1: ausblenden | U1: ausblenden
B2: =Translations!$B$10 | E2: =Translations!$B$11 | G2: =HYPERLINK("#"&ADDRESS(2,3,,,a_Contents!$U$2),a_Contents!$B$2) | I2: =HYPERLINK("#"&ADDRESS(2,3,,,G_FurtherGuidance!$U$2),G_FurtherGuidance!$B$2) | K2: =HYPERLINK("#"&ADDRESS(2,3,,,Summary_Processes!$Y$2),Summary_Processes!$Y$2) | M2: =HYPERLINK("#"&ADDRESS(2,3,,,Summary_Products!$BF$2),Summary_Products!$BF$2) | R2: Print area: | S2: =ADDRESS(ROW($B$6),COLUMN($B$6)) & ":" & ADDRESS(MATCH("PRINT",$P:$P,0),COLUMN($O$6)) | T2: Name of this sheet | U2: =IF(ISERROR(CELL("filename",V2)),"a_Contents",MID(CELL("filename",V2),FIND("]",CELL("filename",V2))+1,1024))
C6: =Translations!$B$12
C8: 0. | D8: =HYPERLINK("#"&S8,INDIRECT(S8)) | S8: =ADDRESS(6,3,,,T8) | T8: ='0_Versions'!$U$2
C10: a. | D10: =HYPERLINK("#"&S10,INDIRECT(S10)) | S10: =ADDRESS(6,3,,,T10) | T10: =$U$2
C12: b. | D12: =HYPERLINK("#"&S12,INDIRECT(S12)) | S12: =ADDRESS(6,3,,,T12) | T12: ='b_Guidelines&Conditions'!$U$2
C14: c. | D14: =HYPERLINK("#"&S14,INDIRECT(S14)) | S14: =ADDRESS(6,3,,,T14) | T14: =c_CodeLists!$U$2
C16: A. | D16: =HYPERLINK("#"&S16,INDIRECT(S16)) | S16: =ADDRESS(6,5,,,T16) | T16: =A_InstData!$U$2
D17: 1 | E17: =HYPERLINK("#"&S17,INDIRECT(S17)) | S17: =ADDRESS(MATCH(D17,INDIRECT("'"& T17 & "'!A:A")),4,,,T17) | T17: =T16
D18: 2 | E18: =HYPERLINK("#"&S18,INDIRECT(S18)) | S18: =ADDRESS(MATCH(D18,INDIRECT("'"& T18 & "'!A:A")),4,,,T18) | T18: =T17
D19: 3 | E19: =HYPERLINK("#"&S19,INDIRECT(S19)) | S19: =ADDRESS(MATCH(D19,INDIRECT("'"& T19 & "'!A:A")),4,,,T19) | T19: =T18
D20: 4 | E20: =HYPERLINK("#"&S20,INDIRECT(S20)) | S20: =ADDRESS(MATCH(D20,INDIRECT("'"& T20 & "'!A:A")),4,,,T20) | T20: =T19
D21: 5 | E21: =HYPERLINK("#"&S21,INDIRECT(S21)) | S21: =ADDRESS(MATCH(D21,INDIRECT("'"& T21 & "'!A:A")),4,,,T21) | T21: =T20
C23: B. | D23: =HYPERLINK("#"&S23,INDIRECT(S23)) | S23: =ADDRESS(6,4,,,T23) | T23: =B_EmInst!$BD$2
D24: 1 | E24: =HYPERLINK("#"&S24,INDIRECT(S24)) | S24: =ADDRESS(MATCH(D24,INDIRECT("'"& T24 & "'!A:A")),4,,,T24) | T24: =T23
D25: 2 | E25: =HYPERLINK("#"&S25,INDIRECT(S25)) | S25: =ADDRESS(MATCH(D25,INDIRECT("'"& T25 & "'!A:A")),4,,,T25) | T25: =T24
D26: 3 | E26: =HYPERLINK("#"&S26,INDIRECT(S26)) | S26: =ADDRESS(MATCH(D26,INDIRECT("'"& T26 & "'!A:A")),4,,,T26) | T26: =T25
C28: C. | D28: =HYPERLINK("#"&S28,INDIRECT(S28)) | S28: =ADDRESS(6,5,,,T28) | T28: ='C_Emissions&Energy'!$U$2
D29: 1 | E29: =HYPERLINK("#"&S29,INDIRECT(S29)) | S29: =ADDRESS(MATCH(D29,INDIRECT("'"& T29 & "'!A:A")),4,,,T29) | T29: =T28
D30: 2 | E30: =HYPERLINK("#"&S30,INDIRECT(S30)) | S30: =ADDRESS(MATCH(D30,INDIRECT("'"& T30 & "'!A:A")),4,,,T30) | T30: =T29
C32: D. | D32: =HYPERLINK("#"&S32,INDIRECT(S32)) | S32: =ADDRESS(7,5,,,T32) | T32: =D_Processes!$U$2
D33: 1 | E33: =HYPERLINK("#"&S33,INDIRECT(S33)) | S33: =ADDRESS(MATCH(D33,INDIRECT("'"& T33 & "'!A:A")),4,,,T33) | T33: =T32
C35: E. | D35: =HYPERLINK("#"&S35,INDIRECT(S35)) | S35: =ADDRESS(8,5,,,T35) | T35: =E_PurchPrec!$U$2
D36: 1 | E36: =HYPERLINK("#"&S36,INDIRECT(S36)) | S36: =ADDRESS(MATCH(D36,INDIRECT("'"& T36 & "'!A:A")),4,,,T36) | T36: =T35
C38: F. | D38: =HYPERLINK("#"&S38,INDIRECT(S38)) | S38: =ADDRESS(6,5,,,T38) | T38: =F_Tools!$U$2
D39: 1 | E39: =HYPERLINK("#"&S39,INDIRECT(S39)) | S39: =ADDRESS(MATCH(D39,INDIRECT("'"& T39 & "'!A:A")),4,,,T39) | T39: =T38
D40: 2 | E40: =HYPERLINK("#"&S40,INDIRECT(S40)) | S40: =ADDRESS(MATCH(D40,INDIRECT("'"& T40 & "'!A:A")),4,,,T40) | T40: =T39
C42: G. | D42: =HYPERLINK("#"&S42,INDIRECT(S42)) | S42: =ADDRESS(6,5,,,T42) | T42: =G_FurtherGuidance!$U$2
D43: 1 | E43: =HYPERLINK("#"&S43,INDIRECT(S43)) | S43: =ADDRESS(MATCH(D43,INDIRECT("'"& T43 & "'!A:A")),4,,,T43) | T43: =T42
D44: 2 | E44: =HYPERLINK("#"&S44,INDIRECT(S44)) | S44: =ADDRESS(MATCH(D44,INDIRECT("'"& T44 & "'!A:A")),4,,,T44) | T44: =T43
D45: 3 | E45: =HYPERLINK("#"&S45,INDIRECT(S45)) | S45: =ADDRESS(MATCH(D45,INDIRECT("'"& T45 & "'!A:A")),4,,,T45) | T45: =T44
D46: 4 | E46: =HYPERLINK("#"&S46,INDIRECT(S46)) | S46: =ADDRESS(MATCH(D46,INDIRECT("'"& T46 & "'!A:A")),4,,,T46) | T46: =T45
D47: 5 | E47: =HYPERLINK("#"&S47,INDIRECT(S47)) | S47: =ADDRESS(MATCH(D47,INDIRECT("'"& T47 & "'!A:A")),4,,,T47) | T47: =T46
D50: =Translations!$B$13
D51: =HYPERLINK("#"&S51,INDIRECT(S51)) | S51: =ADDRESS(2,2,,,T51) | T51: =Summary_Processes!$Y$2
D52: =HYPERLINK("#"&S52,INDIRECT(S52)) | S52: =ADDRESS(2,2,,,T52) | T52: =Summary_Products!$BF$2
D54: =Translations!$B$14
D55: =HYPERLINK("#"&S55,INDIRECT(S55)) | S55: =ADDRESS(2,2,,,T55) | T55: =Summary_Communication!$BE$2
D59: =Translations!$B$15 | H59: =INDEX(Translations!$C$4:$M$4,Translations!A3-2)
D60: =Translations!$B$16 | H60: =VersionDocumentation!C3
...

Sheet b_Guidelines&Conditions
A1: ausblenden | P1: ausblenden | Q1: ausblenden | R1: ausblenden | S1: ausblenden | T1: ausblenden | U1: ausblenden
B2: =Translations!$B$22 | E2: =Translations!$B$11 | G2: =HYPERLINK("#"&ADDRESS(2,3,,,a_Contents!$U$2),a_Contents!$B$2) | I2: =HYPERLINK("#"&ADDRESS(2,3,,,G_FurtherGuidance!$U$2),G_FurtherGuidance!$B$2) | K2: =HYPERLINK("#"&ADDRESS(2,3,,,Summary_Processes!$Y$2),Summary_Processes!$Y$2) | M2: =HYPERLINK("#"&ADDRESS(2,3,,,Summary_Products!$BF$2),Summary_Products!$BF$2) | R2: Print area: | S2: =ADDRESS(ROW($B$6),COLUMN($B$6)) & ":" & ADDRESS(MATCH("PRINT",$P:$P,0),COLUMN($O$6)) | T2: Name of this sheet | U2: =IF(ISERROR(CELL("filename",V2)),"b_Guidelines&Conditions",MID(CELL("filename",V2),FIND("]",CELL("filename",V2))+1,1024))
G3: =IFERROR(HYPERLINK("#"&ADDRESS(ROW($A$1)+MATCH(R3,$A:$A,0)-1,COLUMN($A$1)),INDEX($R:$R,MATCH(R3,$A:$A,0))),"") | I3: =IFERROR(HYPERLINK("#"&ADDRESS(ROW($A$1)+MATCH(T3,$A:$A,0)-1,COLUMN($A$1)),INDEX($R:$R,MATCH(T3,$A:$A,0))),"") | R3: 1 | T3: 2
C6: =Translations!$B$23
A8: 1 | C8: =Translations!$B$24 | R8: General information
B10: 1 | C10: =Translations!$B$26
C11: =HYPERLINK(Translations!$B$27,Translations!$B$27)
B12: 2 | C12: =Translations!$B$1915
C13: =HYPERLINK(Translations!$B$1916,Translations!$B$1916)
B14: 3 | C14: =Translations!$B$30
B15: 4 | C15: =Translations!$B$31
C16: =Translations!$B$32
B17: 5 | C17: =Translations!$B$1917
A19: 2 | C19: =Translations!$B$34 | R19: =C19
B21: 6 | C21: =Translations!$B$35
C22: =Translations!$B$36
B23: 7 | C23: =Translations!$B$1918
B24: 8 | C24: =Translations!$B$38
B25: 9 | C25: =Translations!$B$39
C26: =Translations!$B$1919
B28: 10 | C28: =Translations!$B$41
D29: =Translations!$B$42 | F29: =Translations!$B$43
D30: =Translations!$B$44 | F30: =Translations!$B$45
F31: =Translations!$B$46
F32: =Translations!$B$47
F33: =Translations!$B$48
D34: =CONST_NA | F34: =Translations!$B$1920
F35: =Translations!$B$50
D37: =Translations!$B$1921
E38: =Translations!$B$52
E39: =Translations!$B$53
E40: =Translations!$B$54
B42: 11 | C42: =Translations!$B$55
B43: 12 | C43: =Translations!$B$56
B44: 13 | C44: =Translations!$B$57
B46: 14 | C46: =Translations!$B$58
C48: =Translations!$B$59
C49: =Translations!$B$60 | F49: =HYPERLINK(Translations!$B$61,Translations!$B$61)
C50: =Translations!$B$62 | F50: =HYPERLINK(Translations!$B$63,Translations!$B$63)
A52: ausblenden | P52: PRINT

Sheet c_CodeLists
A1: ausblenden | P1: ausblenden | Q1: ausblenden | R1: ausblenden | S1: ausblenden | T1: ausblenden | U1: ausblenden | V1: ausblenden | W1: ausblenden | X1: ausblenden
B2: =Translations!$B$1438 | E2: =Translations!$B$11 | G2: =HYPERLINK("#"&ADDRESS(2,3,,,a_Contents!$U$2),a_Contents!$B$2) | I2: =HYPERLINK("#"&ADDRESS(2,3,,,G_FurtherGuidance!$U$2),G_FurtherGuidance!$B$2) | K2: =HYPERLINK("#"&ADDRESS(2,3,,,Summary_Processes!$Y$2),Summary_Processes!$Y$2) | M2: =HYPERLINK("#"&ADDRESS(2,3,,,Summary_Products!$BF$2),Summary_Products!$BF$2) | R2: Print area: | S2: =ADDRESS(ROW($B$2),COLUMN(B2)) & ":" & ADDRESS(MATCH("PRINT",$P:$P,0),COLUMN(O4)) | T2: Name of this sheet | U2: =IF(ISERROR(CELL("filename",V2)),"c_CodeLists",MID(CELL("filename",V2),FIND("]",CELL("filename",V2))+1,1024))
G3: =IFERROR(HYPERLINK("#"&ADDRESS(ROW($A$1)+MATCH(R3,$A:$A,0)-1,3),INDEX($R:$R,MATCH(R3,$A:$A,0))),"") | I3: =IFERROR(HYPERLINK("#"&ADDRESS(ROW($A$1)+MATCH(T3,$A:$A,0)-1,3),INDEX($R:$R,MATCH(T3,$A:$A,0))),"") | R3: 1 | T3: 2
C6: =Translations!$B$1439 | R6: Marker | S6: EmbedEm | V6: Errors | X6: Cond. form.
A8: =C8 | C8: 1 | D8: =Translations!$B$1440 | R8: =D8 | S8: =C8
F10: =Translations!$B$1441 | G10: =Translations!$B$1442 | K10: =Translations!$B$1441 | L10: =Translations!$B$1443 | S10: CNTR_ListCountriesCode | T10: CNTR_ListCountriesName | U10: CNTR_ListCurrenciesCode | V10: CNTR_ListCurrenciesName
E11: 1 | F11: AD | G11: =Translations!$B$1444 | J11: 1 | K11: AED | L11: =Translations!$B$1445
E12: 2 | F12: AE | G12: =Translations!$B$1446 | J12: 2 | K12: AFN | L12: =Translations!$B$1447
E13: 3 | F13: AF | G13: =Translations!$B$1448 | J13: 3 | K13: ALL | L13: =Translations!$B$1449
E14: 4 | F14: AG | G14: =Translations!$B$1450 | J14: 4 | K14: AMD | L14: =Translations!$B$1451
E15: 5 | F15: AI | G15: =Translations!$B$1452 | J15: 5 | K15: ANG | L15: =Translations!$B$1453
E16: 6 | F16: AL | G16: =Translations!$B$1454 | J16: 6 | K16: AOA | L16: =Translations!$B$1455
E17: 7 | F17: AM | G17: =Translations!$B$1456 | J17: 7 | K17: ARS | L17: =Translations!$B$1457
E18: 8 | F18: AN | G18: =Translations!$B$1458 | J18: 8 | K18: AUD | L18: =Translations!$B$1459
E19: 9 | F19: AO | G19: =Translations!$B$1460 | J19: 9 | K19: AWG | L19: =Translations!$B$1461
E20: 10 | F20: AQ | G20: =Translations!$B$1461 | J20: 10 | K20: AZN | L20: =Translations!$B$1463
E21: 11 | F21: AR | G21: =Translations!$B$1464 | J21: 11 | K21: BAM | L21: =Translations!$B$1465
E22: 12 | F22: AS | G22: =Translations!$B$1466 | J22: 12 | K22: BBD | L22: =Translations!$B$1467
E23: 13 | F23: AT | G23: =Translations!$B$1922 | J23: 13 | K23: BDT | L23: =Translations!$B$1468
E24: 14 | F24: AU | G24: =Translations!$B$1469 | J24: 14 | K24: BGN | L24: =Translations!$B$1470
E25: 15 | F25: AW | G25: =Translations!$B$1471 | J25: 15 | K25: BHD | L25: =Translations!$B$1472
E26: 16 | F26: AX | G26: =Translations!$B$1473 | J26: 16 | K26: BIF | L26: =Translations!$B$1474
E27: 17 | F27: AZ | G27: =Translations!$B$1475 | J27: 17 | K27: BMD | L27: =Translations!$B$1476
E28: 18 | F28: BA | G28: =Translations!$B$1477 | J28: 18 | K28: BND | L28: =Translations!$B$1478
E29: 19 | F29: BB | G29: =Translations!$B$1479 | J29: 19 | K29: BOB | L29: =Translations!$B$1480
E30: 20 | F30: BD | G30: =Translations!$B$1481 | J30: 20 | K30: BOV | L30: =Translations!$B$1482
E31: 21 | F31: BE | G31: =Translations!$B$1923 | J31: 21 | K31: BRL | L31: =Translations!$B$1483
E32: 22 | F32: BF | G32: =Translations!$B$1484 | J32: 22 | K32: BSD | L32: =Translations!$B$1485
E33: 23 | F33: BG | G33: =Translations!$B$1924 | J33: 23 | K33: BTN | L33: =Translations!$B$1486
E34: 24 | F34: BH | G34: =Translations!$B$1487 | J34: 24 | K34: BWP | L34: =Translations!$B$1488
E35: 25 | F35: BI | G35: =Translations!$B$1489 | J35: 25 | K35: BYN | L35: =Translations!$B$1490
E36: 26 | F36: BJ | G36: =Translations!$B$1491 | J36: 26 | K36: BZD | L36: =Translations!$B$1492
E37: 27 | F37: BL | G37: =Translations!$B$1493 | J37: 27 | K37: CAD | L37: =Translations!$B$1494
E38: 28 | F38: BM | G38: =Translations!$B$1495 | J38: 28 | K38: CDF | L38: =Translations!$B$1496
E39: 29 | F39: BN | G39: =Translations!$B$1497 | J39: 29 | K39: CHE | L39: =Translations!$B$1498
E40: 30 | F40: BO | G40: =Translations!$B$1499 | J40: 30 | K40: CHF | L40: =Translations!$B$1500
E41: 31 | F41: BQ | G41: =Translations!$B$1501 | J41: 31 | K41: CHW | L41: =Translations!$B$1502
E42: 32 | F42: BR | G42: =Translations!$B$1503 | J42: 32 | K42: CLF | L42: =Translations!$B$1504
E43: 33 | F43: BS | G43: =Translations!$B$1505 | J43: 33 | K43: CLP | L43: =Translations!$B$1506
E44: 34 | F44: BT | G44: =Translations!$B$1507 | J44: 34 | K44: CNY | L44: =Translations!$B$1508
...

Sheet A_InstData
A1: ausblenden | P1: ausblenden | Q1: ausblenden | R1: ausblenden | S1: ausblenden | T1: ausblenden | U1: ausblenden | V1: ausblenden | W1: ausblenden | X1: ausblenden | Y1: ausblenden | Z1: ausblenden | AA1: ausblenden | AB1: ausblenden | AC1: ausblenden | AD1: ausblenden | AE1: ausblenden | AF1: ausblenden | AG1: ausblenden | AH1: ausblenden | AI1: ausblenden
B2: =Translations!$B$64 | E2: =Translations!$B$11 | G2: =HYPERLINK("#"&ADDRESS(2,3,,,a_Contents!$U$2),a_Contents!$B$2) | I2: =HYPERLINK("#"&ADDRESS(2,3,,,G_FurtherGuidance!$U$2),G_FurtherGuidance!$B$2) | K2: =HYPERLINK("#"&ADDRESS(2,3,,,Summary_Processes!$Y$2),Summary_Processes!$Y$2) | M2: =HYPERLINK("#"&ADDRESS(2,3,,,Summary_Products!$BF$2),Summary_Products!$BF$2) | R2: Print area: | S2: =ADDRESS(ROW($B$6),COLUMN($B$55)) & ":" & ADDRESS(MATCH("PRINT",$P:$P,0),COLUMN($O$55)) | T2: Name of this sheet | U2: =IF(ISERROR(CELL("filename",V2)),"A_InstData",MID(CELL("filename",V2),FIND("]",CELL("filename",V2))+1,1024))
G3: =IFERROR(HYPERLINK("#"&ADDRESS(ROW($A$1)+MATCH(R3,$A:$A,0)-1,3),INDEX($R:$R,MATCH(R3,$A:$A,0))),"") | I3: =IFERROR(HYPERLINK("#"&ADDRESS(ROW($A$1)+MATCH(T3,$A:$A,0)-1,3),INDEX($R:$R,MATCH(T3,$A:$A,0))),"") | K3: =IFERROR(HYPERLINK("#"&ADDRESS(ROW($A$1)+MATCH(V3,$A:$A,0)-1,3),INDEX($R:$R,MATCH(V3,$A:$A,0))),"") | M3: =IFERROR(HYPERLINK("#"&ADDRESS(ROW($A$1)+MATCH(X3,$A:$A,0)-1,3),INDEX($R:$R,MATCH(X3,$A:$A,0))),"") | R3: 1 | T3: 2 | V3: 3 | X3: 4
G4: =IFERROR(HYPERLINK("#"&ADDRESS(ROW($A$1)+MATCH(R4,$A:$A,0)-1,3),INDEX($R:$R,MATCH(R4,$A:$A,0))),"") | R4: 5
C6: A. | E6: =Translations!$B$65 | R6: Marker | AG6: Errors | AI6: Cond. form.
A9: =C9 | C9: 1 | D9: =Translations!$B$67 | H9: =Translations!$B$68 | I9: 44562 | K9: =Translations!$B$69 | L9: 44926 | R9: =D9 | AG9: =IF(AND(CNTR_HasEntriesA,COUNTA(I9,L9)<2),CONST_ErrorOrMissing&A9,CONST_NA)
E13: =Translations!$B$1952
E14: =Translations!$B$71
A17: =C17 | C17: 2 | D17: =Translations!$B$72 | R17: =D17
D19: i. | E19: =Translations!$B$73 | I19: Ulsan Steel Plant 22
D20: ii. | E20: =Translations!$B$74 | I20: Ulsan Steel Plant 22 | AG20: =IF(AND(CNTR_HasEntriesA,I20=""),CONST_ErrorOrMissing&A17,CONST_NA)
D21: iii. | E21: =Translations!$B$75 | I21: Steel Way, 20
D22: iv. | E22: =Translations!$B$76 | I22: Blast furnace operation
D23: v. | E23: =Translations!$B$77 | I23: 305293
D24: vi. | E24: =Translations!$B$78 | I24: ROC
D25: vii. | E25: =Translations!$B$79 | I25: Ulsan
D26: viii. | E26: =Translations!$B$80 | I26: South Korea | S26: =IF(I26="","",INDEX(CNTR_ListCountriesCode,MATCH(I26,CNTR_ListCountriesName,0))) | AG26: =IF(AND(CNTR_HasEntriesA,I26=""),CONST_ErrorOrMissing&A17,CONST_NA)
D27: ix. | E27: =Translations!$B$81 | I27: KRRIV
D28: x. | E28: =Translations!$B$82 | I28: -24.1625416°
D29: xi. | E29: =Translations!$B$83 | I29: 163.199359°
D30: xii. | E30: =Translations!$B$84 | I30: Maria Tanaka
D31: xiii. | E31: =Translations!$B$85 | I31: maria.tanaka@example-steel.com
D32: xiv. | E32: =Translations!$B$86 | I32: +2 865617976
A34: =C34 | C34: 3 | D34: =Translations!$B$87 | R34: Verifier
D36: (a) | E36: =Translations!$B$89
D37: i. | E37: =Translations!$B$90
D38: ii. | E38: =Translations!$B$75
D39: iii. | E39: =Translations!$B$79
D40: iv. | E40: =Translations!$B$91
D41: v. | E41: =Translations!$B$80
D43: (b) | E43: =Translations!$B$92
E44: =Translations!$B$93
D45: i. | E45: =Translations!$B$94
D46: ii. | E46: =Translations!$B$95
D47: iii. | E47: =Translations!$B$96
D48: iv. | E48: =Translations!$B$97
D50: (c) | E50: =Translations!$B$98
D51: i. | E51: =Translations!$B$99
D52: ii. | E52: =Translations!$B$100
D53: iii. | E53: =Translations!$B$101
...

Sheet B_EmInst
A1: ausblenden | T1: ausblenden | U1: ausblenden | AB1: ausblenden | AC1: ausblenden | AW1: ausblenden | AZ1: ausblenden | BA1: ausblenden | BB1: ausblenden | BC1: ausblenden | BD1: ausblenden | BE1: ausblenden | BF1: ausblenden | BG1: ausblenden | BH1: ausblenden | BI1: ausblenden | BJ1: ausblenden | BK1: ausblenden | BL1: ausblenden | BM1: ausblenden | BN1: ausblenden | BO1: ausblenden | BP1: ausblenden | BQ1: ausblenden | BR1: ausblenden | BS1: ausblenden | BT1: ausblenden | BU1: ausblenden | BV1: ausblenden | BW1: ausblenden
B2: =Translations!$B$127 | E2: =Translations!$B$11 | G2: =HYPERLINK("#"&ADDRESS(2,3,,,a_Contents!$U$2),a_Contents!$B$2) | I2: =HYPERLINK("#"&ADDRESS(2,3,,,G_FurtherGuidance!$U$2),G_FurtherGuidance!$B$2) | K2: =HYPERLINK("#"&ADDRESS(2,3,,,Summary_Processes!$Y$2),Summary_Processes!$Y$2) | M2: =HYPERLINK("#"&ADDRESS(2,3,,,Summary_Products!$BF$2),Summary_Products!$BF$2) | BA2: Print area: | BB2: =ADDRESS(ROW($B$8),COLUMN($B$8)) & ":" & ADDRESS(MATCH("PRINT",$AZ:$AZ,0),COLUMN($AZ$8)) | BC2: Name of this sheet | BD2: =IF(ISERROR(CELL("filename",BE2)),"B_EmInst",MID(CELL("filename",BE2),FIND("]",CELL("filename",BE2))+1,1024))
G3: =IFERROR(HYPERLINK("#"&ADDRESS(ROW($A$1)+MATCH(BA3,$A:$A,0)-1,3),INDEX($BA:$BA,MATCH(BA3,$A:$A,0))),"") | I3: =IFERROR(HYPERLINK("#"&ADDRESS(ROW($A$1)+MATCH(BC3,$A:$A,0)-1,3),INDEX($BA:$BA,MATCH(BC3,$A:$A,0))),"") | K3: =IFERROR(HYPERLINK("#"&ADDRESS(ROW($A$1)+MATCH(BE3,$A:$A,0)-1,3),INDEX($BA:$BA,MATCH(BE3,$A:$A,0))),"") | BA3: 1 | BC3: 2 | BE3: 3
C6: B. | D6: =Translations!$B$128
C8: 1 | D8: =Translations!$B$129
D10: =HYPERLINK("#"&ADDRESS(MATCH($BB10,G_FurtherGuidance!$S:$S,0),3,,,G_FurtherGuidance!$U$2),CONST_LinkToGuidanceSheet) | BA10: Link to guidance: | BB10: 2
A12: 1 | C12: (a) | D12: =Translations!$B$1958 | T12: Delete | U12: Delete | AB12: Delete | AC12: Delete | AW12: Delete | BA12: Source streams | BD12: fossil | BH12: biomass | BL12: Cond. Formats --> True = white | BP12: True = light yellow | BR12: Error of FALSE | BW12: Cond. Formats
C13: =Translations!$B$131 | D13: =Translations!$B$132 | E13: =Translations!$B$133 | F13: =Translations!$B$134 | G13: =Translations!$B$135 | H13: =Translations!$B$136 | I13: =Translations!$B$137 | J13: =Translations!$B$138 | K13: =Translations!$B$139 | L13: =Translations!$B$140 | M13: =Translations!$B$141 | N13: =Translations!$B$142 | O13: =Translations!$B$143 | P13: =Translations!$B$144 | Q13: =Translations!$B$145 | R13: =Translations!$B$146 | S13: =Translations!$B$147 | T13: non-sust. BioC | U13: non-sust. BioC Unit | V13: =Translations!$B$150 | W13: =Translations!$B$151 | X13: =Translations!$B$152 | Y13: =Translations!$B$153 | Z13: =Translations!$B$1959 | AA13: =Translations!$B$1960 | AB13: Flue gas (total) | AC13: Flue gas (total), Unit | AD13: =Translations!$B$158 | AE13: =Translations!$B$159 | AF13: =Translations!$B$1961 | AG13: =Translations!$B$161 | AH13: =Translations!$B$162 | AI13: =Translations!$B$163 | AJ13: =Translations!$B$164 | AK13: =Translations!$B$165 | AL13: =Translations!$B$166 | AM13: =Translations!$B$167 | AN13: =Translations!$B$168 | AO13: =Translations!$B$169 | AP13: =Translations!$B$170 | AQ13: =Translations!$B$171 | AR13: =Translations!$B$172 | AS13: =Translations!$B$173 | AT13: =Translations!$B$174 | AU13: =Translations!$B$175 | AV13: =Translations!$B$176 | AW13: CO2e non-sust. bio (t) | AX13: =Translations!$B$178 | AY13: =Translations!$B$179 | BD13: Combustion | BE13: Process | BF13: Mass Balance | BH13: Combustion | BI13: Process | BJ13: Mass Balance | BL13: Emission factor (EF) | BM13: CC | BN13: OxF | BO13: ConvF | BP13: NCV | BR13: AD+EF Units consistent? | BS13: Complete-ness? Combustion | BT13: Complete-ness? Process | BU13: Complete-ness? Mass balance
C14: =Translations!$B$180 | D14: =Translations!$B$181 | E14: =Translations!$B$182 | F14: 252000 | G14: t | H14: 45 | I14: =IF(E14="","",IF(G14="","", IF(G14=CONST_kNm3,CONST_GJpkNm3,CONST_GJpt))) | J14: 73 | K14: =Translations!$B$184 | M14: =IF(D14<>INDEX(CONST_MonitoringApproach,3),"", IF(G14="","", CONST_tC&"/"&IF(G14="",CONST_t,G14))) | N14: 100 | O14: % | Q14: % | R14: 0 | S14: % | U14: % | AU14: =IF($D14="","",IF(BR14=FALSE(),CONST_ERR_Inconsistent,IF(COUNTIF(BS14:BU14,FALSE())>0,CONST_ERR_Incomplete,SUM(BD14:BF14)))) | AV14: =IF(ISNUMBER(AU14),SUM(BH14:BJ14),"") | AX14: =IF($D14="","",$F14*$H14/1000*(1-$R14/100)) | AY14: =IF($D14="","",$F14*$H14/1000*($R14/100)) | BD14: =IF($D14<>INDEX(CONST_MonitoringApproach,1),"",$F14*IF($K14=CONST_tCO2pTJ,$H14/1000,1)*$J14*IF($N14="",1,$N14/100)*(1-$R14/100)) | BE14: =IF($D14<>INDEX(CONST_MonitoringApproach,2),"",$F14*IF($K14=CONST_tCO2pTJ,$H14/1000,1)*$J14*IF($P14="",1,$P14/100)*(1-$R14/100)) | BF14: =IF($D14<>INDEX(CONST_MonitoringApproach,3),"",$F14*$L14*3.664*(1-$R14/100)) | BH14: =IF($D14<>INDEX(CONST_MonitoringApproach,1),"",$F14*IF($K14=CONST_tCO2pTJ,$H14/1000,1)*$J14*IF($N14="",1,$N14/100)*($R14/100)) | BI14: =IF($D14<>INDEX(CONST_MonitoringApproach,2),"",$F14*IF($K14=CONST_tCO2pTJ,$H14/1000,1)*$J14*IF($P14="",1,$P14/100)*($R14/100)) | BJ14: =IF($D14<>INDEX(CONST_MonitoringApproach,3),"",$F14*$L14*3.664*($R14/100)) | BR14: =IF($D14="","",OR(AND($G14 = INDEX(CONST_torkNm3,1), $K14=INDEX(CONST_tCO2pTJOrtCO2pt,2)),AND($G14 = INDEX(CONST_torkNm3,2),$K14=INDEX(CONST_tCO2pTJOrtCO2pt,3)),$K14=INDEX(CONST_tCO2pTJOrtCO2pt,1),$D14=INDEX(CONST_MonitoringApproach,3))) | BS14: =IF($D14<>INDEX(CONST_MonitoringApproach,1),"", AND(COUNTA($E14,$G14,$K14)=3,COUNT($F14,$J14)=2,IF($K14=CONST_tCO2pTJ,ISNUMBER($H14),TRUE()))) | BT14: =IF($D14<>INDEX(CONST_MonitoringApproach,2),"", AND(COUNTA($E14,$G14,$K14)=3,COUNT($F14,$J14)=2,IF($K14=CONST_tCO2pTJ,ISNUMBER($H14),TRUE()))) | BU14: =IF($D14<>INDEX(CONST_MonitoringApproach,3),"",AND(COUNTA($E14,$G14)=2,COUNT($F14,$L14)=2))
C15: =Translations!$B$185 | D15: =Translations!$B$186 | E15: =Translations!$B$187 | F15: 121000 | G15: t | I15: =IF(E15="","",IF(G15="","", IF(G15=CONST_kNm3,CONST_GJpkNm3,CONST_GJpt))) | J15: 0.08794 | K15: =Translations!$B$188 | M15: =IF(D15<>INDEX(CONST_MonitoringApproach,3),"", IF(G15="","", CONST_tC&"/"&IF(G15="",CONST_t,G15))) | O15: % | P15: 100 | Q15: % | R15: 0 | S15: % | U15: % | AU15: =IF($D15="","",IF(BR15=FALSE(),CONST_ERR_Inconsistent,IF(COUNTIF(BS15:BU15,FALSE())>0,CONST_ERR_Incomplete,SUM(BD15:BF15)))) | AV15: =IF(ISNUMBER(AU15),SUM(BH15:BJ15),"") | AX15: =IF($D15="","",$F15*$H15/1000*(1-$R15/100)) | AY15: =IF($D15="","",$F15*$H15/1000*($R15/100)) | BD15: =IF($D15<>INDEX(CONST_MonitoringApproach,1),"",$F15*IF($K15=CONST_tCO2pTJ,$H15/1000,1)*$J15*IF($N15="",1,$N15/100)*(1-$R15/100)) | BE15: =IF($D15<>INDEX(CONST_MonitoringApproach,2),"",$F15*IF($K15=CONST_tCO2pTJ,$H15/1000,1)*$J15*IF($P15="",1,$P15/100)*(1-$R15/100)) | BF15: =IF($D15<>INDEX(CONST_MonitoringApproach,3),"",$F15*$L15*3.664*(1-$R15/100)) | BH15: =IF($D15<>INDEX(CONST_MonitoringApproach,1),"",$F15*IF($K15=CONST_tCO2pTJ,$H15/1000,1)*$J15*IF($N15="",1,$N15/100)*($R15/100)) | BI15: =IF($D15<>INDEX(CONST_MonitoringApproach,2),"",$F15*IF($K15=CONST_tCO2pTJ,$H15/1000,1)*$J15*IF($P15="",1,$P15/100)*($R15/100)) | BJ15: =IF($D15<>INDEX(CONST_MonitoringApproach,3),"",$F15*$L15*3.664*($R15/100)) | BR15: =IF($D15="","",OR(AND($G15 = INDEX(CONST_torkNm3,1), $K15=INDEX(CONST_tCO2pTJOrtCO2pt,2)),AND($G15 = INDEX(CONST_torkNm3,2),$K15=INDEX(CONST_tCO2pTJOrtCO2pt,3)),$K15=INDEX(CONST_tCO2pTJOrtCO2pt,1),$D15=INDEX(CONST_MonitoringApproach,3))) | BS15: =IF($D15<>INDEX(CONST_MonitoringApproach,1),"", AND(COUNTA($E15,$G15,$K15)=3,COUNT($F15,$J15)=2,IF($K15=CONST_tCO2pTJ,ISNUMBER($H15),TRUE()))) | BT15: =IF($D15<>INDEX(CONST_MonitoringApproach,2),"", AND(COUNTA($E15,$G15,$K15)=3,COUNT($F15,$J15)=2,IF($K15=CONST_tCO2pTJ,ISNUMBER($H15),TRUE()))) | BU15: =IF($D15<>INDEX(CONST_MonitoringApproach,3),"",AND(COUNTA($E15,$G15)=2,COUNT($F15,$L15)=2))
C16: =Translations!$B$189 | D16: =Translations!$B$190 | E16: =Translations!$B$191 | F16: -1808226 | G16: t | I16: =IF(E16="","",IF(G16="","", IF(G16=CONST_kNm3,CONST_GJpkNm3,CONST_GJpt))) | L16: 0.003878 | M16: =IF(D16<>INDEX(CONST_MonitoringApproach,3),"", IF(G16="","", CONST_tC&"/"&IF(G16="",CONST_t,G16))) | O16: % | Q16: % | R16: 0 | S16: % | U16: % | AU16: =IF($D16="","",IF(BR16=FALSE(),CONST_ERR_Inconsistent,IF(COUNTIF(BS16:BU16,FALSE())>0,CONST_ERR_Incomplete,SUM(BD16:BF16)))) | AV16: =IF(ISNUMBER(AU16),SUM(BH16:BJ16),"") | AX16: =IF($D16="","",$F16*$H16/1000*(1-$R16/100)) | AY16: =IF($D16="","",$F16*$H16/1000*($R16/100)) | BD16: =IF($D16<>INDEX(CONST_MonitoringApproach,1),"",$F16*IF($K16=CONST_tCO2pTJ,$H16/1000,1)*$J16*IF($N16="",1,$N16/100)*(1-$R16/100)) | BE16: =IF($D16<>INDEX(CONST_MonitoringApproach,2),"",$F16*IF($K16=CONST_tCO2pTJ,$H16/1000,1)*$J16*IF($P16="",1,$P16/100)*(1-$R16/100)) | BF16: =IF($D16<>INDEX(CONST_MonitoringApproach,3),"",$F16*$L16*3.664*(1-$R16/100)) | BH16: =IF($D16<>INDEX(CONST_MonitoringApproach,1),"",$F16*IF($K16=CONST_tCO2pTJ,$H16/1000,1)*$J16*IF($N16="",1,$N16/100)*($R16/100)) | BI16: =IF($D16<>INDEX(CONST_MonitoringApproach,2),"",$F16*IF($K16=CONST_tCO2pTJ,$H16/1000,1)*$J16*IF($P16="",1,$P16/100)*($R16/100)) | BJ16: =IF($D16<>INDEX(CONST_MonitoringApproach,3),"",$F16*$L16*3.664*($R16/100)) | BR16: =IF($D16="","",OR(AND($G16 = INDEX(CONST_torkNm3,1), $K16=INDEX(CONST_tCO2pTJOrtCO2pt,2)),AND($G16 = INDEX(CONST_torkNm3,2),$K16=INDEX(CONST_tCO2pTJOrtCO2pt,3)),$K16=INDEX(CONST_tCO2pTJOrtCO2pt,1),$D16=INDEX(CONST_MonitoringApproach,3))) | BS16: =IF($D16<>INDEX(CONST_MonitoringApproach,1),"", AND(COUNTA($E16,$G16,$K16)=3,COUNT($F16,$J16)=2,IF($K16=CONST_tCO2pTJ,ISNUMBER($H16),TRUE()))) | BT16: =IF($D16<>INDEX(CONST_MonitoringApproach,2),"", AND(COUNTA($E16,$G16,$K16)=3,COUNT($F16,$J16)=2,IF($K16=CONST_tCO2pTJ,ISNUMBER($H16),TRUE()))) | BU16: =IF($D16<>INDEX(CONST_MonitoringApproach,3),"",AND(COUNTA($E16,$G16)=2,COUNT($F16,$L16)=2))
C17: 1 | D17: Mass Balance | E17: Coke fines | F17: 50000 | G17: t | H17: 28.2 | I17: =IF(E17="","",IF(G17="","", IF(G17=CONST_kNm3,CONST_GJpkNm3,CONST_GJpt))) | L17: 0.88 | M17: =IF(D17<>INDEX(CONST_MonitoringApproach,3),"", IF(G17="","", CONST_tC&"/"&IF(G17="",CONST_t,G17))) | O17: % | Q17: % | S17: % | U17: % | AU17: =IF($D17="","",IF(BR17=FALSE(),CONST_ERR_Inconsistent,IF(COUNTIF(BS17:BU17,FALSE())>0,CONST_ERR_Incomplete,SUM(BD17:BF17)))) | AV17: =IF(ISNUMBER(AU17),SUM(BH17:BJ17),"") | AX17: =IF($D17="","",$F17*$H17/1000*(1-$R17/100)) | AY17: =IF($D17="","",$F17*$H17/1000*($R17/100)) | BA17: =CONST_CNTR_SUM_CO2 | BD17: =IF($D17<>INDEX(CONST_MonitoringApproach,1),"",$F17*IF($K17=CONST_tCO2pTJ,$H17/1000,1)*$J17*IF($N17="",1,$N17/100)*(1-$R17/100)) | BE17: =IF($D17<>INDEX(CONST_MonitoringApproach,2),"",$F17*IF($K17=CONST_tCO2pTJ,$H17/1000,1)*$J17*IF($P17="",1,$P17/100)*(1-$R17/100)) | BF17: =IF($D17<>INDEX(CONST_MonitoringApproach,3),"",$F17*$L17*3.664*(1-$R17/100)) | BH17: =IF($D17<>INDEX(CONST_MonitoringApproach,1),"",$F17*IF($K17=CONST_tCO2pTJ,$H17/1000,1)*$J17*IF($N17="",1,$N17/100)*($R17/100)) | BI17: =IF($D17<>INDEX(CONST_MonitoringApproach,2),"",$F17*IF($K17=CONST_tCO2pTJ,$H17/1000,1)*$J17*IF($P17="",1,$P17/100)*($R17/100)) | BJ17: =IF($D17<>INDEX(CONST_MonitoringApproach,3),"",$F17*$L17*3.664*($R17/100)) | BL17: =IF($D17="","",MATCH($D17,CONST_MonitoringApproach,0)=3) | BM17: =IF($D17="","",MATCH($D17,CONST_MonitoringApproach,0)<>3) | BN17: =IF($D17="","",MATCH($D17,CONST_MonitoringApproach,0)<>1) | BO17: =IF($D17="","",MATCH($D17,CONST_MonitoringApproach,0)<>2) | BP17: =OR($K17<>CONST_tCO2pTJ,$D17=INDEX(CONST_MonitoringApproach,3)) | BR17: =IF($D17="","",OR(AND($G17 = INDEX(CONST_torkNm3,1), $K17=INDEX(CONST_tCO2pTJOrtCO2pt,2)),AND($G17 = INDEX(CONST_torkNm3,2),$K17=INDEX(CONST_tCO2pTJOrtCO2pt,3)),$K17=INDEX(CONST_tCO2pTJOrtCO2pt,1),$D17=INDEX(CONST_MonitoringApproach,3))) | BS17: =IF($D17<>INDEX(CONST_MonitoringApproach,1),"", AND(COUNTA($E17,$G17,$K17)=3,COUNT($F17,$J17)=2,IF($K17=CONST_tCO2pTJ,ISNUMBER($H17),TRUE()))) | BT17: =IF($D17<>INDEX(CONST_MonitoringApproach,2),"", AND(COUNTA($E17,$G17,$K17)=3,COUNT($F17,$J17)=2,IF($K17=CONST_tCO2pTJ,ISNUMBER($H17),TRUE()))) | BU17: =IF($D17<>INDEX(CONST_MonitoringApproach,3),"",AND(COUNTA($E17,$G17)=2,COUNT($F17,$L17)=2)) | BW17: =AND(CNTR_HasEntriesA,D17="")
C18: 2 | D18: Mass Balance | E18: Iron ores | F18: 5600000 | G18: t | I18: =IF(E18="","",IF(G18="","", IF(G18=CONST_kNm3,CONST_GJpkNm3,CONST_GJpt))) | L18: 0.00023 | M18: =IF(D18<>INDEX(CONST_MonitoringApproach,3),"", IF(G18="","", CONST_tC&"/"&IF(G18="",CONST_t,G18))) | O18: % | Q18: % | S18: % | U18: % | AU18: =IF($D18="","",IF(BR18=FALSE(),CONST_ERR_Inconsistent,IF(COUNTIF(BS18:BU18,FALSE())>0,CONST_ERR_Incomplete,SUM(BD18:BF18)))) | AV18: =IF(ISNUMBER(AU18),SUM(BH18:BJ18),"") | AX18: =IF($D18="","",$F18*$H18/1000*(1-$R18/100)) | AY18: =IF($D18="","",$F18*$H18/1000*($R18/100)) | BA18: =CONST_CNTR_SUM_CO2 | BD18: =IF($D18<>INDEX(CONST_MonitoringApproach,1),"",$F18*IF($K18=CONST_tCO2pTJ,$H18/1000,1)*$J18*IF($N18="",1,$N18/100)*(1-$R18/100)) | BE18: =IF($D18<>INDEX(CONST_MonitoringApproach,2),"",$F18*IF($K18=CONST_tCO2pTJ,$H18/1000,1)*$J18*IF($P18="",1,$P18/100)*(1-$R18/100)) | BF18: =IF($D18<>INDEX(CONST_MonitoringApproach,3),"",$F18*$L18*3.664*(1-$R18/100)) | BH18: =IF($D18<>INDEX(CONST_MonitoringApproach,1),"",$F18*IF($K18=CONST_tCO2pTJ,$H18/1000,1)*$J18*IF($N18="",1,$N18/100)*($R18/100)) | BI18: =IF($D18<>INDEX(CONST_MonitoringApproach,2),"",$F18*IF($K18=CONST_tCO2pTJ,$H18/1000,1)*$J18*IF($P18="",1,$P18/100)*($R18/100)) | BJ18: =IF($D18<>INDEX(CONST_MonitoringApproach,3),"",$F18*$L18*3.664*($R18/100)) | BL18: =IF($D18="","",MATCH($D18,CONST_MonitoringApproach,0)=3) | BM18: =IF($D18="","",MATCH($D18,CONST_MonitoringApproach,0)<>3) | BN18: =IF($D18="","",MATCH($D18,CONST_MonitoringApproach,0)<>1) | BO18: =IF($D18="","",MATCH($D18,CONST_MonitoringApproach,0)<>2) | BP18: =OR($K18<>CONST_tCO2pTJ,$D18=INDEX(CONST_MonitoringApproach,3)) | BR18: =IF($D18="","",OR(AND($G18 = INDEX(CONST_torkNm3,1), $K18=INDEX(CONST_tCO2pTJOrtCO2pt,2)),AND($G18 = INDEX(CONST_torkNm3,2),$K18=INDEX(CONST_tCO2pTJOrtCO2pt,3)),$K18=INDEX(CONST_tCO2pTJOrtCO2pt,1),$D18=INDEX(CONST_MonitoringApproach,3))) | BS18: =IF($D18<>INDEX(CONST_MonitoringApproach,1),"", AND(COUNTA($E18,$G18,$K18)=3,COUNT($F18,$J18)=2,IF($K18=CONST_tCO2pTJ,ISNUMBER($H18),TRUE()))) | BT18: =IF($D18<>INDEX(CONST_MonitoringApproach,2),"", AND(COUNTA($E18,$G18,$K18)=3,COUNT($F18,$J18)=2,IF($K18=CONST_tCO2pTJ,ISNUMBER($H18),TRUE()))) | BU18: =IF($D18<>INDEX(CONST_MonitoringApproach,3),"",AND(COUNTA($E18,$G18)=2,COUNT($F18,$L18)=2)) | BW18: =AND(CNTR_HasEntriesA,D18="")
C19: 3 | D19: Mass Balance | E19: Coke | F19: 2200000 | G19: t | H19: 28.2 | I19: =IF(E19="","",IF(G19="","", IF(G19=CONST_kNm3,CONST_GJpkNm3,CONST_GJpt))) | L19: 0.88 | M19: =IF(D19<>INDEX(CONST_MonitoringApproach,3),"", IF(G19="","", CONST_tC&"/"&IF(G19="",CONST_t,G19))) | O19: % | Q19: % | S19: % | U19: % | AU19: =IF($D19="","",IF(BR19=FALSE(),CONST_ERR_Inconsistent,IF(COUNTIF(BS19:BU19,FALSE())>0,CONST_ERR_Incomplete,SUM(BD19:BF19)))) | AV19: =IF(ISNUMBER(AU19),SUM(BH19:BJ19),"") | AX19: =IF($D19="","",$F19*$H19/1000*(1-$R19/100)) | AY19: =IF($D19="","",$F19*$H19/1000*($R19/100)) | BA19: =CONST_CNTR_SUM_CO2 | BD19: =IF($D19<>INDEX(CONST_MonitoringApproach,1),"",$F19*IF($K19=CONST_tCO2pTJ,$H19/1000,1)*$J19*IF($N19="",1,$N19/100)*(1-$R19/100)) | BE19: =IF($D19<>INDEX(CONST_MonitoringApproach,2),"",$F19*IF($K19=CONST_tCO2pTJ,$H19/1000,1)*$J19*IF($P19="",1,$P19/100)*(1-$R19/100)) | BF19: =IF($D19<>INDEX(CONST_MonitoringApproach,3),"",$F19*$L19*3.664*(1-$R19/100)) | BH19: =IF($D19<>INDEX(CONST_MonitoringApproach,1),"",$F19*IF($K19=CONST_tCO2pTJ,$H19/1000,1)*$J19*IF($N19="",1,$N19/100)*($R19/100)) | BI19: =IF($D19<>INDEX(CONST_MonitoringApproach,2),"",$F19*IF($K19=CONST_tCO2pTJ,$H19/1000,1)*$J19*IF($P19="",1,$P19/100)*($R19/100)) | BJ19: =IF($D19<>INDEX(CONST_MonitoringApproach,3),"",$F19*$L19*3.664*($R19/100)) | BL19: =IF($D19="","",MATCH($D19,CONST_MonitoringApproach,0)=3) | BM19: =IF($D19="","",MATCH($D19,CONST_MonitoringApproach,0)<>3) | BN19: =IF($D19="","",MATCH($D19,CONST_MonitoringApproach,0)<>1) | BO19: =IF($D19="","",MATCH($D19,CONST_MonitoringApproach,0)<>2) | BP19: =OR($K19<>CONST_tCO2pTJ,$D19=INDEX(CONST_MonitoringApproach,3)) | BR19: =IF($D19="","",OR(AND($G19 = INDEX(CONST_torkNm3,1), $K19=INDEX(CONST_tCO2pTJOrtCO2pt,2)),AND($G19 = INDEX(CONST_torkNm3,2),$K19=INDEX(CONST_tCO2pTJOrtCO2pt,3)),$K19=INDEX(CONST_tCO2pTJOrtCO2pt,1),$D19=INDEX(CONST_MonitoringApproach,3))) | BS19: =IF($D19<>INDEX(CONST_MonitoringApproach,1),"", AND(COUNTA($E19,$G19,$K19)=3,COUNT($F19,$J19)=2,IF($K19=CONST_tCO2pTJ,ISNUMBER($H19),TRUE()))) | BT19: =IF($D19<>INDEX(CONST_MonitoringApproach,2),"", AND(COUNTA($E19,$G19,$K19)=3,COUNT($F19,$J19)=2,IF($K19=CONST_tCO2pTJ,ISNUMBER($H19),TRUE()))) | BU19: =IF($D19<>INDEX(CONST_MonitoringApproach,3),"",AND(COUNTA($E19,$G19)=2,COUNT($F19,$L19)=2)) | BW19: =AND(CNTR_HasEntriesA,D19="")
C20: 4 | D20: Mass Balance | E20: Plastic wastes | F20: 70000 | G20: t | H20: 38 | I20: =IF(E20="","",IF(G20="","", IF(G20=CONST_kNm3,CONST_GJpkNm3,CONST_GJpt))) | L20: 0.68357153 | M20: =IF(D20<>INDEX(CONST_MonitoringApproach,3),"", IF(G20="","", CONST_tC&"/"&IF(G20="",CONST_t,G20))) | O20: % | Q20: % | R20: 16 | S20: % | U20: % | AU20: =IF($D20="","",IF(BR20=FALSE(),CONST_ERR_Inconsistent,IF(COUNTIF(BS20:BU20,FALSE())>0,CONST_ERR_Incomplete,SUM(BD20:BF20)))) | AV20: =IF(ISNUMBER(AU20),SUM(BH20:BJ20),"") | AX20: =IF($D20="","",$F20*$H20/1000*(1-$R20/100)) | AY20: =IF($D20="","",$F20*$H20/1000*($R20/100)) | BA20: =CONST_CNTR_SUM_CO2 | BD20: =IF($D20<>INDEX(CONST_MonitoringApproach,1),"",$F20*IF($K20=CONST_tCO2pTJ,$H20/1000,1)*$J20*IF($N20="",1,$N20/100)*(1-$R20/100)) | BE20: =IF($D20<>INDEX(CONST_MonitoringApproach,2),"",$F20*IF($K20=CONST_tCO2pTJ,$H20/1000,1)*$J20*IF($P20="",1,$P20/100)*(1-$R20/100)) | BF20: =IF($D20<>INDEX(CONST_MonitoringApproach,3),"",$F20*$L20*3.664*(1-$R20/100)) | BH20: =IF($D20<>INDEX(CONST_MonitoringApproach,1),"",$F20*IF($K20=CONST_tCO2pTJ,$H20/1000,1)*$J20*IF($N20="",1,$N20/100)*($R20/100)) | BI20: =IF($D20<>INDEX(CONST_MonitoringApproach,2),"",$F20*IF($K20=CONST_tCO2pTJ,$H20/1000,1)*$J20*IF($P20="",1,$P20/100)*($R20/100)) | BJ20: =IF($D20<>INDEX(CONST_MonitoringApproach,3),"",$F20*$L20*3.664*($R20/100)) | BL20: =IF($D20="","",MATCH($D20,CONST_MonitoringApproach,0)=3) | BM20: =IF($D20="","",MATCH($D20,CONST_MonitoringApproach,0)<>3) | BN20: =IF($D20="","",MATCH($D20,CONST_MonitoringApproach,0)<>1) | BO20: =IF($D20="","",MATCH($D20,CONST_MonitoringApproach,0)<>2) | BP20: =OR($K20<>CONST_tCO2pTJ,$D20=INDEX(CONST_MonitoringApproach,3)) | BR20: =IF($D20="","",OR(AND($G20 = INDEX(CONST_torkNm3,1), $K20=INDEX(CONST_tCO2pTJOrtCO2pt,2)),AND($G20 = INDEX(CONST_torkNm3,2),$K20=INDEX(CONST_tCO2pTJOrtCO2pt,3)),$K20=INDEX(CONST_tCO2pTJOrtCO2pt,1),$D20=INDEX(CONST_MonitoringApproach,3))) | BS20: =IF($D20<>INDEX(CONST_MonitoringApproach,1),"", AND(COUNTA($E20,$G20,$K20)=3,COUNT($F20,$J20)=2,IF($K20=CONST_tCO2pTJ,ISNUMBER($H20),TRUE()))) | BT20: =IF($D20<>INDEX(CONST_MonitoringApproach,2),"", AND(COUNTA($E20,$G20,$K20)=3,COUNT($F20,$J20)=2,IF($K20=CONST_tCO2pTJ,ISNUMBER($H20),TRUE()))) | BU20: =IF($D20<>INDEX(CONST_MonitoringApproach,3),"",AND(COUNTA($E20,$G20)=2,COUNT($F20,$L20)=2)) | BW20: =AND(CNTR_HasEntriesA,D20="")
C21: 5 | D21: Mass Balance | E21: Scrap (external) | F21: 800000 | G21: t | I21: =IF(E21="","",IF(G21="","", IF(G21=CONST_kNm3,CONST_GJpkNm3,CONST_GJpt))) | L21: 0.0021 | M21: =IF(D21<>INDEX(CONST_MonitoringApproach,3),"", IF(G21="","", CONST_tC&"/"&IF(G21="",CONST_t,G21))) | O21: % | Q21: % | S21: % | U21: % | AU21: =IF($D21="","",IF(BR21=FALSE(),CONST_ERR_Inconsistent,IF(COUNTIF(BS21:BU21,FALSE())>0,CONST_ERR_Incomplete,SUM(BD21:BF21)))) | AV21: =IF(ISNUMBER(AU21),SUM(BH21:BJ21),"") | AX21: =IF($D21="","",$F21*$H21/1000*(1-$R21/100)) | AY21: =IF($D21="","",$F21*$H21/1000*($R21/100)) | BA21: =CONST_CNTR_SUM_CO2 | BD21: =IF($D21<>INDEX(CONST_MonitoringApproach,1),"",$F21*IF($K21=CONST_tCO2pTJ,$H21/1000,1)*$J21*IF($N21="",1,$N21/100)*(1-$R21/100)) | BE21: =IF($D21<>INDEX(CONST_MonitoringApproach,2),"",$F21*IF($K21=CONST_tCO2pTJ,$H21/1000,1)*$J21*IF($P21="",1,$P21/100)*(1-$R21/100)) | BF21: =IF($D21<>INDEX(CONST_MonitoringApproach,3),"",$F21*$L21*3.664*(1-$R21/100)) | BH21: =IF($D21<>INDEX(CONST_MonitoringApproach,1),"",$F21*IF($K21=CONST_tCO2pTJ,$H21/1000,1)*$J21*IF($N21="",1,$N21/100)*($R21/100)) | BI21: =IF($D21<>INDEX(CONST_MonitoringApproach,2),"",$F21*IF($K21=CONST_tCO2pTJ,$H21/1000,1)*$J21*IF($P21="",1,$P21/100)*($R21/100)) | BJ21: =IF($D21<>INDEX(CONST_MonitoringApproach,3),"",$F21*$L21*3.664*($R21/100)) | BL21: =IF($D21="","",MATCH($D21,CONST_MonitoringApproach,0)=3) | BM21: =IF($D21="","",MATCH($D21,CONST_MonitoringApproach,0)<>3) | BN21: =IF($D21="","",MATCH($D21,CONST_MonitoringApproach,0)<>1) | BO21: =IF($D21="","",MATCH($D21,CONST_MonitoringApproach,0)<>2) | BP21: =OR($K21<>CONST_tCO2pTJ,$D21=INDEX(CONST_MonitoringApproach,3)) | BR21: =IF($D21="","",OR(AND($G21 = INDEX(CONST_torkNm3,1), $K21=INDEX(CONST_tCO2pTJOrtCO2pt,2)),AND($G21 = INDEX(CONST_torkNm3,2),$K21=INDEX(CONST_tCO2pTJOrtCO2pt,3)),$K21=INDEX(CONST_tCO2pTJOrtCO2pt,1),$D21=INDEX(CONST_MonitoringApproach,3))) | BS21: =IF($D21<>INDEX(CONST_MonitoringApproach,1),"", AND(COUNTA($E21,$G21,$K21)=3,COUNT($F21,$J21)=2,IF($K21=CONST_tCO2pTJ,ISNUMBER($H21),TRUE()))) | BT21: =IF($D21<>INDEX(CONST_MonitoringApproach,2),"", AND(COUNTA($E21,$G21,$K21)=3,COUNT($F21,$J21)=2,IF($K21=CONST_tCO2pTJ,ISNUMBER($H21),TRUE()))) | BU21: =IF($D21<>INDEX(CONST_MonitoringApproach,3),"",AND(COUNTA($E21,$G21)=2,COUNT($F21,$L21)=2)) | BW21: =AND(CNTR_HasEntriesA,D21="")
C22: 6 | D22: Mass Balance | E22: Scrap (internal) | F22: 200000 | G22: t | I22: =IF(E22="","",IF(G22="","", IF(G22=CONST_kNm3,CONST_GJpkNm3,CONST_GJpt))) | L22: 0.0018 | M22: =IF(D22<>INDEX(CONST_MonitoringApproach,3),"", IF(G22="","", CONST_tC&"/"&IF(G22="",CONST_t,G22))) | O22: % | Q22: % | S22: % | U22: % | AU22: =IF($D22="","",IF(BR22=FALSE(),CONST_ERR_Inconsistent,IF(COUNTIF(BS22:BU22,FALSE())>0,CONST_ERR_Incomplete,SUM(BD22:BF22)))) | AV22: =IF(ISNUMBER(AU22),SUM(BH22:BJ22),"") | AX22: =IF($D22="","",$F22*$H22/1000*(1-$R22/100)) | AY22: =IF($D22="","",$F22*$H22/1000*($R22/100)) | BA22: =CONST_CNTR_SUM_CO2 | BD22: =IF($D22<>INDEX(CONST_MonitoringApproach,1),"",$F22*IF($K22=CONST_tCO2pTJ,$H22/1000,1)*$J22*IF($N22="",1,$N22/100)*(1-$R22/100)) | BE22: =IF($D22<>INDEX(CONST_MonitoringApproach,2),"",$F22*IF($K22=CONST_tCO2pTJ,$H22/1000,1)*$J22*IF($P22="",1,$P22/100)*(1-$R22/100)) | BF22: =IF($D22<>INDEX(CONST_MonitoringApproach,3),"",$F22*$L22*3.664*(1-$R22/100)) | BH22: =IF($D22<>INDEX(CONST_MonitoringApproach,1),"",$F22*IF($K22=CONST_tCO2pTJ,$H22/1000,1)*$J22*IF($N22="",1,$N22/100)*($R22/100)) | BI22: =IF($D22<>INDEX(CONST_MonitoringApproach,2),"",$F22*IF($K22=CONST_tCO2pTJ,$H22/1000,1)*$J22*IF($P22="",1,$P22/100)*($R22/100)) | BJ22: =IF($D22<>INDEX(CONST_MonitoringApproach,3),"",$F22*$L22*3.664*($R22/100)) | BL22: =IF($D22="","",MATCH($D22,CONST_MonitoringApproach,0)=3) | BM22: =IF($D22="","",MATCH($D22,CONST_MonitoringApproach,0)<>3) | BN22: =IF($D22="","",MATCH($D22,CONST_MonitoringApproach,0)<>1) | BO22: =IF($D22="","",MATCH($D22,CONST_MonitoringApproach,0)<>2) | BP22: =OR($K22<>CONST_tCO2pTJ,$D22=INDEX(CONST_MonitoringApproach,3)) | BR22: =IF($D22="","",OR(AND($G22 = INDEX(CONST_torkNm3,1), $K22=INDEX(CONST_tCO2pTJOrtCO2pt,2)),AND($G22 = INDEX(CONST_torkNm3,2),$K22=INDEX(CONST_tCO2pTJOrtCO2pt,3)),$K22=INDEX(CONST_tCO2pTJOrtCO2pt,1),$D22=INDEX(CONST_MonitoringApproach,3))) | BS22: =IF($D22<>INDEX(CONST_MonitoringApproach,1),"", AND(COUNTA($E22,$G22,$K22)=3,COUNT($F22,$J22)=2,IF($K22=CONST_tCO2pTJ,ISNUMBER($H22),TRUE()))) | BT22: =IF($D22<>INDEX(CONST_MonitoringApproach,2),"", AND(COUNTA($E22,$G22,$K22)=3,COUNT($F22,$J22)=2,IF($K22=CONST_tCO2pTJ,ISNUMBER($H22),TRUE()))) | BU22: =IF($D22<>INDEX(CONST_MonitoringApproach,3),"",AND(COUNTA($E22,$G22)=2,COUNT($F22,$L22)=2)) | BW22: =AND(CNTR_HasEntriesA,D22="")
C23: 7 | D23: Mass Balance | E23: Lime calcined | F23: 280000 | G23: t | I23: =IF(E23="","",IF(G23="","", IF(G23=CONST_kNm3,CONST_GJpkNm3,CONST_GJpt))) | L23: 0.0027292576 | M23: =IF(D23<>INDEX(CONST_MonitoringApproach,3),"", IF(G23="","", CONST_tC&"/"&IF(G23="",CONST_t,G23))) | O23: % | Q23: % | S23: % | U23: % | AU23: =IF($D23="","",IF(BR23=FALSE(),CONST_ERR_Inconsistent,IF(COUNTIF(BS23:BU23,FALSE())>0,CONST_ERR_Incomplete,SUM(BD23:BF23)))) | AV23: =IF(ISNUMBER(AU23),SUM(BH23:BJ23),"") | AX23: =IF($D23="","",$F23*$H23/1000*(1-$R23/100)) | AY23: =IF($D23="","",$F23*$H23/1000*($R23/100)) | BA23: =CONST_CNTR_SUM_CO2 | BD23: =IF($D23<>INDEX(CONST_MonitoringApproach,1),"",$F23*IF($K23=CONST_tCO2pTJ,$H23/1000,1)*$J23*IF($N23="",1,$N23/100)*(1-$R23/100)) | BE23: =IF($D23<>INDEX(CONST_MonitoringApproach,2),"",$F23*IF($K23=CONST_tCO2pTJ,$H23/1000,1)*$J23*IF($P23="",1,$P23/100)*(1-$R23/100)) | BF23: =IF($D23<>INDEX(CONST_MonitoringApproach,3),"",$F23*$L23*3.664*(1-$R23/100)) | BH23: =IF($D23<>INDEX(CONST_MonitoringApproach,1),"",$F23*IF($K23=CONST_tCO2pTJ,$H23/1000,1)*$J23*IF($N23="",1,$N23/100)*($R23/100)) | BI23: =IF($D23<>INDEX(CONST_MonitoringApproach,2),"",$F23*IF($K23=CONST_tCO2pTJ,$H23/1000,1)*$J23*IF($P23="",1,$P23/100)*($R23/100)) | BJ23: =IF($D23<>INDEX(CONST_MonitoringApproach,3),"",$F23*$L23*3.664*($R23/100)) | BL23: =IF($D23="","",MATCH($D23,CONST_MonitoringApproach,0)=3) | BM23: =IF($D23="","",MATCH($D23,CONST_MonitoringApproach,0)<>3) | BN23: =IF($D23="","",MATCH($D23,CONST_MonitoringApproach,0)<>1) | BO23: =IF($D23="","",MATCH($D23,CONST_MonitoringApproach,0)<>2) | BP23: =OR($K23<>CONST_tCO2pTJ,$D23=INDEX(CONST_MonitoringApproach,3)) | BR23: =IF($D23="","",OR(AND($G23 = INDEX(CONST_torkNm3,1), $K23=INDEX(CONST_tCO2pTJOrtCO2pt,2)),AND($G23 = INDEX(CONST_torkNm3,2),$K23=INDEX(CONST_tCO2pTJOrtCO2pt,3)),$K23=INDEX(CONST_tCO2pTJOrtCO2pt,1),$D23=INDEX(CONST_MonitoringApproach,3))) | BS23: =IF($D23<>INDEX(CONST_MonitoringApproach,1),"", AND(COUNTA($E23,$G23,$K23)=3,COUNT($F23,$J23)=2,IF($K23=CONST_tCO2pTJ,ISNUMBER($H23),TRUE()))) | BT23: =IF($D23<>INDEX(CONST_MonitoringApproach,2),"", AND(COUNTA($E23,$G23,$K23)=3,COUNT($F23,$J23)=2,IF($K23=CONST_tCO2pTJ,ISNUMBER($H23),TRUE()))) | BU23: =IF($D23<>INDEX(CONST_MonitoringApproach,3),"",AND(COUNTA($E23,$G23)=2,COUNT($F23,$L23)=2)) | BW23: =AND(CNTR_HasEntriesA,D23="")
C24: 8 | D24: Mass Balance | E24: Natural gas | F24: 170000 | G24: t | H24: 48 | I24: =IF(E24="","",IF(G24="","", IF(G24=CONST_kNm3,CONST_GJpkNm3,CONST_GJpt))) | L24: 0.75 | M24: =IF(D24<>INDEX(CONST_MonitoringApproach,3),"", IF(G24="","", CONST_tC&"/"&IF(G24="",CONST_t,G24))) | O24: % | Q24: % | S24: % | U24: % | AU24: =IF($D24="","",IF(BR24=FALSE(),CONST_ERR_Inconsistent,IF(COUNTIF(BS24:BU24,FALSE())>0,CONST_ERR_Incomplete,SUM(BD24:BF24)))) | AV24: =IF(ISNUMBER(AU24),SUM(BH24:BJ24),"") | AX24: =IF($D24="","",$F24*$H24/1000*(1-$R24/100)) | AY24: =IF($D24="","",$F24*$H24/1000*($R24/100)) | BA24: =CONST_CNTR_SUM_CO2 | BD24: =IF($D24<>INDEX(CONST_MonitoringApproach,1),"",$F24*IF($K24=CONST_tCO2pTJ,$H24/1000,1)*$J24*IF($N24="",1,$N24/100)*(1-$R24/100)) | BE24: =IF($D24<>INDEX(CONST_MonitoringApproach,2),"",$F24*IF($K24=CONST_tCO2pTJ,$H24/1000,1)*$J24*IF($P24="",1,$P24/100)*(1-$R24/100)) | BF24: =IF($D24<>INDEX(CONST_MonitoringApproach,3),"",$F24*$L24*3.664*(1-$R24/100)) | BH24: =IF($D24<>INDEX(CONST_MonitoringApproach,1),"",$F24*IF($K24=CONST_tCO2pTJ,$H24/1000,1)*$J24*IF($N24="",1,$N24/100)*($R24/100)) | BI24: =IF($D24<>INDEX(CONST_MonitoringApproach,2),"",$F24*IF($K24=CONST_tCO2pTJ,$H24/1000,1)*$J24*IF($P24="",1,$P24/100)*($R24/100)) | BJ24: =IF($D24<>INDEX(CONST_MonitoringApproach,3),"",$F24*$L24*3.664*($R24/100)) | BL24: =IF($D24="","",MATCH($D24,CONST_MonitoringApproach,0)=3) | BM24: =IF($D24="","",MATCH($D24,CONST_MonitoringApproach,0)<>3) | BN24: =IF($D24="","",MATCH($D24,CONST_MonitoringApproach,0)<>1) | BO24: =IF($D24="","",MATCH($D24,CONST_MonitoringApproach,0)<>2) | BP24: =OR($K24<>CONST_tCO2pTJ,$D24=INDEX(CONST_MonitoringApproach,3)) | BR24: =IF($D24="","",OR(AND($G24 = INDEX(CONST_torkNm3,1), $K24=INDEX(CONST_tCO2pTJOrtCO2pt,2)),AND($G24 = INDEX(CONST_torkNm3,2),$K24=INDEX(CONST_tCO2pTJOrtCO2pt,3)),$K24=INDEX(CONST_tCO2pTJOrtCO2pt,1),$D24=INDEX(CONST_MonitoringApproach,3))) | BS24: =IF($D24<>INDEX(CONST_MonitoringApproach,1),"", AND(COUNTA($E24,$G24,$K24)=3,COUNT($F24,$J24)=2,IF($K24=CONST_tCO2pTJ,ISNUMBER($H24),TRUE()))) | BT24: =IF($D24<>INDEX(CONST_MonitoringApproach,2),"", AND(COUNTA($E24,$G24,$K24)=3,COUNT($F24,$J24)=2,IF($K24=CONST_tCO2pTJ,ISNUMBER($H24),TRUE()))) | BU24: =IF($D24<>INDEX(CONST_MonitoringApproach,3),"",AND(COUNTA($E24,$G24)=2,COUNT($F24,$L24)=2)) | BW24: =AND(CNTR_HasEntriesA,D24="")
C25: 9 | D25: Mass Balance | E25: Other inputs | F25: 40000 | G25: t | I25: =IF(E25="","",IF(G25="","", IF(G25=CONST_kNm3,CONST_GJpkNm3,CONST_GJpt))) | L25: 0.1 | M25: =IF(D25<>INDEX(CONST_MonitoringApproach,3),"", IF(G25="","", CONST_tC&"/"&IF(G25="",CONST_t,G25))) | O25: % | Q25: % | S25: % | U25: % | AU25: =IF($D25="","",IF(BR25=FALSE(),CONST_ERR_Inconsistent,IF(COUNTIF(BS25:BU25,FALSE())>0,CONST_ERR_Incomplete,SUM(BD25:BF25)))) | AV25: =IF(ISNUMBER(AU25),SUM(BH25:BJ25),"") | AX25: =IF($D25="","",$F25*$H25/1000*(1-$R25/100)) | AY25: =IF($D25="","",$F25*$H25/1000*($R25/100)) | BA25: =CONST_CNTR_SUM_CO2 | BD25: =IF($D25<>INDEX(CONST_MonitoringApproach,1),"",$F25*IF($K25=CONST_tCO2pTJ,$H25/1000,1)*$J25*IF($N25="",1,$N25/100)*(1-$R25/100)) | BE25: =IF($D25<>INDEX(CONST_MonitoringApproach,2),"",$F25*IF($K25=CONST_tCO2pTJ,$H25/1000,1)*$J25*IF($P25="",1,$P25/100)*(1-$R25/100)) | BF25: =IF($D25<>INDEX(CONST_MonitoringApproach,3),"",$F25*$L25*3.664*(1-$R25/100)) | BH25: =IF($D25<>INDEX(CONST_MonitoringApproach,1),"",$F25*IF($K25=CONST_tCO2pTJ,$H25/1000,1)*$J25*IF($N25="",1,$N25/100)*($R25/100)) | BI25: =IF($D25<>INDEX(CONST_MonitoringApproach,2),"",$F25*IF($K25=CONST_tCO2pTJ,$H25/1000,1)*$J25*IF($P25="",1,$P25/100)*($R25/100)) | BJ25: =IF($D25<>INDEX(CONST_MonitoringApproach,3),"",$F25*$L25*3.664*($R25/100)) | BL25: =IF($D25="","",MATCH($D25,CONST_MonitoringApproach,0)=3) | BM25: =IF($D25="","",MATCH($D25,CONST_MonitoringApproach,0)<>3) | BN25: =IF($D25="","",MATCH($D25,CONST_MonitoringApproach,0)<>1) | BO25: =IF($D25="","",MATCH($D25,CONST_MonitoringApproach,0)<>2) | BP25: =OR($K25<>CONST_tCO2pTJ,$D25=INDEX(CONST_MonitoringApproach,3)) | BR25: =IF($D25="","",OR(AND($G25 = INDEX(CONST_torkNm3,1), $K25=INDEX(CONST_tCO2pTJOrtCO2pt,2)),AND($G25 = INDEX(CONST_torkNm3,2),$K25=INDEX(CONST_tCO2pTJOrtCO2pt,3)),$K25=INDEX(CONST_tCO2pTJOrtCO2pt,1),$D25=INDEX(CONST_MonitoringApproach,3))) | BS25: =IF($D25<>INDEX(CONST_MonitoringApproach,1),"", AND(COUNTA($E25,$G25,$K25)=3,COUNT($F25,$J25)=2,IF($K25=CONST_tCO2pTJ,ISNUMBER($H25),TRUE()))) | BT25: =IF($D25<>INDEX(CONST_MonitoringApproach,2),"", AND(COUNTA($E25,$G25,$K25)=3,COUNT($F25,$J25)=2,IF($K25=CONST_tCO2pTJ,ISNUMBER($H25),TRUE()))) | BU25: =IF($D25<>INDEX(CONST_MonitoringApproach,3),"",AND(COUNTA($E25,$G25)=2,COUNT($F25,$L25)=2)) | BW25: =AND(CNTR_HasEntriesA,D25="")
C26: 10 | D26: Mass Balance | E26: Steel | F26: -4800000 | G26: t | I26: =IF(E26="","",IF(G26="","", IF(G26=CONST_kNm3,CONST_GJpkNm3,CONST_GJpt))) | L26: 0.0018 | M26: =IF(D26<>INDEX(CONST_MonitoringApproach,3),"", IF(G26="","", CONST_tC&"/"&IF(G26="",CONST_t,G26))) | O26: % | Q26: % | S26: % | U26: % | AU26: =IF($D26="","",IF(BR26=FALSE(),CONST_ERR_Inconsistent,IF(COUNTIF(BS26:BU26,FALSE())>0,CONST_ERR_Incomplete,SUM(BD26:BF26)))) | AV26: =IF(ISNUMBER(AU26),SUM(BH26:BJ26),"") | AX26: =IF($D26="","",$F26*$H26/1000*(1-$R26/100)) | AY26: =IF($D26="","",$F26*$H26/1000*($R26/100)) | BA26: =CONST_CNTR_SUM_CO2 | BD26: =IF($D26<>INDEX(CONST_MonitoringApproach,1),"",$F26*IF($K26=CONST_tCO2pTJ,$H26/1000,1)*$J26*IF($N26="",1,$N26/100)*(1-$R26/100)) | BE26: =IF($D26<>INDEX(CONST_MonitoringApproach,2),"",$F26*IF($K26=CONST_tCO2pTJ,$H26/1000,1)*$J26*IF($P26="",1,$P26/100)*(1-$R26/100)) | BF26: =IF($D26<>INDEX(CONST_MonitoringApproach,3),"",$F26*$L26*3.664*(1-$R26/100)) | BH26: =IF($D26<>INDEX(CONST_MonitoringApproach,1),"",$F26*IF($K26=CONST_tCO2pTJ,$H26/1000,1)*$J26*IF($N26="",1,$N26/100)*($R26/100)) | BI26: =IF($D26<>INDEX(CONST_MonitoringApproach,2),"",$F26*IF($K26=CONST_tCO2pTJ,$H26/1000,1)*$J26*IF($P26="",1,$P26/100)*($R26/100)) | BJ26: =IF($D26<>INDEX(CONST_MonitoringApproach,3),"",$F26*$L26*3.664*($R26/100)) | BL26: =IF($D26="","",MATCH($D26,CONST_MonitoringApproach,0)=3) | BM26: =IF($D26="","",MATCH($D26,CONST_MonitoringApproach,0)<>3) | BN26: =IF($D26="","",MATCH($D26,CONST_MonitoringApproach,0)<>1) | BO26: =IF($D26="","",MATCH($D26,CONST_MonitoringApproach,0)<>2) | BP26: =OR($K26<>CONST_tCO2pTJ,$D26=INDEX(CONST_MonitoringApproach,3)) | BR26: =IF($D26="","",OR(AND($G26 = INDEX(CONST_torkNm3,1), $K26=INDEX(CONST_tCO2pTJOrtCO2pt,2)),AND($G26 = INDEX(CONST_torkNm3,2),$K26=INDEX(CONST_tCO2pTJOrtCO2pt,3)),$K26=INDEX(CONST_tCO2pTJOrtCO2pt,1),$D26=INDEX(CONST_MonitoringApproach,3))) | BS26: =IF($D26<>INDEX(CONST_MonitoringApproach,1),"", AND(COUNTA($E26,$G26,$K26)=3,COUNT($F26,$J26)=2,IF($K26=CONST_tCO2pTJ,ISNUMBER($H26),TRUE()))) | BT26: =IF($D26<>INDEX(CONST_MonitoringApproach,2),"", AND(COUNTA($E26,$G26,$K26)=3,COUNT($F26,$J26)=2,IF($K26=CONST_tCO2pTJ,ISNUMBER($H26),TRUE()))) | BU26: =IF($D26<>INDEX(CONST_MonitoringApproach,3),"",AND(COUNTA($E26,$G26)=2,COUNT($F26,$L26)=2)) | BW26: =AND(CNTR_HasEntriesA,D26="")
C27: 11 | D27: Mass Balance | E27: Slags | F27: -1000000 | G27: t | I27: =IF(E27="","",IF(G27="","", IF(G27=CONST_kNm3,CONST_GJpkNm3,CONST_GJpt))) | L27: 0.0003 | M27: =IF(D27<>INDEX(CONST_MonitoringApproach,3),"", IF(G27="","", CONST_tC&"/"&IF(G27="",CONST_t,G27))) | O27: % | Q27: % | S27: % | U27: % | AU27: =IF($D27="","",IF(BR27=FALSE(),CONST_ERR_Inconsistent,IF(COUNTIF(BS27:BU27,FALSE())>0,CONST_ERR_Incomplete,SUM(BD27:BF27)))) | AV27: =IF(ISNUMBER(AU27),SUM(BH27:BJ27),"") | AX27: =IF($D27="","",$F27*$H27/1000*(1-$R27/100)) | AY27: =IF($D27="","",$F27*$H27/1000*($R27/100)) | BA27: =CONST_CNTR_SUM_CO2 | BD27: =IF($D27<>INDEX(CONST_MonitoringApproach,1),"",$F27*IF($K27=CONST_tCO2pTJ,$H27/1000,1)*$J27*IF($N27="",1,$N27/100)*(1-$R27/100)) | BE27: =IF($D27<>INDEX(CONST_MonitoringApproach,2),"",$F27*IF($K27=CONST_tCO2pTJ,$H27/1000,1)*$J27*IF($P27="",1,$P27/100)*(1-$R27/100)) | BF27: =IF($D27<>INDEX(CONST_MonitoringApproach,3),"",$F27*$L27*3.664*(1-$R27/100)) | BH27: =IF($D27<>INDEX(CONST_MonitoringApproach,1),"",$F27*IF($K27=CONST_tCO2pTJ,$H27/1000,1)*$J27*IF($N27="",1,$N27/100)*($R27/100)) | BI27: =IF($D27<>INDEX(CONST_MonitoringApproach,2),"",$F27*IF($K27=CONST_tCO2pTJ,$H27/1000,1)*$J27*IF($P27="",1,$P27/100)*($R27/100)) | BJ27: =IF($D27<>INDEX(CONST_MonitoringApproach,3),"",$F27*$L27*3.664*($R27/100)) | BL27: =IF($D27="","",MATCH($D27,CONST_MonitoringApproach,0)=3) | BM27: =IF($D27="","",MATCH($D27,CONST_MonitoringApproach,0)<>3) | BN27: =IF($D27="","",MATCH($D27,CONST_MonitoringApproach,0)<>1) | BO27: =IF($D27="","",MATCH($D27,CONST_MonitoringApproach,0)<>2) | BP27: =OR($K27<>CONST_tCO2pTJ,$D27=INDEX(CONST_MonitoringApproach,3)) | BR27: =IF($D27="","",OR(AND($G27 = INDEX(CONST_torkNm3,1), $K27=INDEX(CONST_tCO2pTJOrtCO2pt,2)),AND($G27 = INDEX(CONST_torkNm3,2),$K27=INDEX(CONST_tCO2pTJOrtCO2pt,3)),$K27=INDEX(CONST_tCO2pTJOrtCO2pt,1),$D27=INDEX(CONST_MonitoringApproach,3))) | BS27: =IF($D27<>INDEX(CONST_MonitoringApproach,1),"", AND(COUNTA($E27,$G27,$K27)=3,COUNT($F27,$J27)=2,IF($K27=CONST_tCO2pTJ,ISNUMBER($H27),TRUE()))) | BT27: =IF($D27<>INDEX(CONST_MonitoringApproach,2),"", AND(COUNTA($E27,$G27,$K27)=3,COUNT($F27,$J27)=2,IF($K27=CONST_tCO2pTJ,ISNUMBER($H27),TRUE()))) | BU27: =IF($D27<>INDEX(CONST_MonitoringApproach,3),"",AND(COUNTA($E27,$G27)=2,COUNT($F27,$L27)=2)) | BW27: =AND(CNTR_HasEntriesA,D27="")
C28: 12 | I28: =IF(E28="","",IF(G28="","", IF(G28=CONST_kNm3,CONST_GJpkNm3,CONST_GJpt))) | M28: =IF(D28<>INDEX(CONST_MonitoringApproach,3),"", IF(G28="","", CONST_tC&"/"&IF(G28="",CONST_t,G28))) | O28: % | Q28: % | S28: % | U28: % | AU28: =IF($D28="","",IF(BR28=FALSE(),CONST_ERR_Inconsistent,IF(COUNTIF(BS28:BU28,FALSE())>0,CONST_ERR_Incomplete,SUM(BD28:BF28)))) | AV28: =IF(ISNUMBER(AU28),SUM(BH28:BJ28),"") | AX28: =IF($D28="","",$F28*$H28/1000*(1-$R28/100)) | AY28: =IF($D28="","",$F28*$H28/1000*($R28/100)) | BA28: =CONST_CNTR_SUM_CO2 | BD28: =IF($D28<>INDEX(CONST_MonitoringApproach,1),"",$F28*IF($K28=CONST_tCO2pTJ,$H28/1000,1)*$J28*IF($N28="",1,$N28/100)*(1-$R28/100)) | BE28: =IF($D28<>INDEX(CONST_MonitoringApproach,2),"",$F28*IF($K28=CONST_tCO2pTJ,$H28/1000,1)*$J28*IF($P28="",1,$P28/100)*(1-$R28/100)) | BF28: =IF($D28<>INDEX(CONST_MonitoringApproach,3),"",$F28*$L28*3.664*(1-$R28/100)) | BH28: =IF($D28<>INDEX(CONST_MonitoringApproach,1),"",$F28*IF($K28=CONST_tCO2pTJ,$H28/1000,1)*$J28*IF($N28="",1,$N28/100)*($R28/100)) | BI28: =IF($D28<>INDEX(CONST_MonitoringApproach,2),"",$F28*IF($K28=CONST_tCO2pTJ,$H28/1000,1)*$J28*IF($P28="",1,$P28/100)*($R28/100)) | BJ28: =IF($D28<>INDEX(CONST_MonitoringApproach,3),"",$F28*$L28*3.664*($R28/100)) | BL28: =IF($D28="","",MATCH($D28,CONST_MonitoringApproach,0)=3) | BM28: =IF($D28="","",MATCH($D28,CONST_MonitoringApproach,0)<>3) | BN28: =IF($D28="","",MATCH($D28,CONST_MonitoringApproach,0)<>1) | BO28: =IF($D28="","",MATCH($D28,CONST_MonitoringApproach,0)<>2) | BP28: =OR($K28<>CONST_tCO2pTJ,$D28=INDEX(CONST_MonitoringApproach,3)) | BR28: =IF($D28="","",OR(AND($G28 = INDEX(CONST_torkNm3,1), $K28=INDEX(CONST_tCO2pTJOrtCO2pt,2)),AND($G28 = INDEX(CONST_torkNm3,2),$K28=INDEX(CONST_tCO2pTJOrtCO2pt,3)),$K28=INDEX(CONST_tCO2pTJOrtCO2pt,1),$D28=INDEX(CONST_MonitoringApproach,3))) | BS28: =IF($D28<>INDEX(CONST_MonitoringApproach,1),"", AND(COUNTA($E28,$G28,$K28)=3,COUNT($F28,$J28)=2,IF($K28=CONST_tCO2pTJ,ISNUMBER($H28),TRUE()))) | BT28: =IF($D28<>INDEX(CONST_MonitoringApproach,2),"", AND(COUNTA($E28,$G28,$K28)=3,COUNT($F28,$J28)=2,IF($K28=CONST_tCO2pTJ,ISNUMBER($H28),TRUE()))) | BU28: =IF($D28<>INDEX(CONST_MonitoringApproach,3),"",AND(COUNTA($E28,$G28)=2,COUNT($F28,$L28)=2)) | BW28: =AND(CNTR_HasEntriesA,D28="")
